<?xml version='1.0'?>
<robot name="rospibot_model_04">

  <material name="red">
    <color rgba="0.8 0 0 1"/>
  </material>

  <material name="green">
    <color rgba="0 0.8 0 1"/>
  </material>

  <material name="blue">
    <color rgba="0 0 0.8 1"/>
  </material>

  <material name="white">
    <color rgba="1 1 1 1"/>
  </material>

  <material name="black">
    <color rgba="0 0 0 1"/>
  </material>

  <material name="transparent">
    <color rgba="1 1 1 0.1"/>
  </material>
  
  <!-- Base Link -->
  <link name="base_link">
    <visual>
      <origin xyz="-0.035 0 0" rpy="0 0 0" />
      <geometry>
	<box size="0.21 0.18 0.004"/>
      </geometry>
      <material name="transparent" />
    </visual>
    <!-- Caster -->
    <visual name="caster">
      <origin xyz="-0.09 0 0" rpy="0 0 0" />
      <geometry>
        <sphere radius="0.034" />
      </geometry>
      <material name="black" />
    </visual> 
  </link>
  
  <!-- Right Wheel -->
  <link name="right_wheel">
    <visual>
      <origin xyz="0 0 0" rpy="1.570795 0 0" />
      <geometry>
          <cylinder length="0.01" radius="0.034" />
      </geometry>
    </visual>
  </link>
  <joint name="joint_right_wheel" type="continuous">
    <parent link="base_link"/>
    <child link="right_wheel"/>
    <origin xyz="0 -0.10 0" rpy="0 0 0" /> 
    <axis xyz="0 1 0" />
  </joint>

  <!-- Left Wheel -->
  <link name="left_wheel">
    <visual>
      <origin xyz="0 0 0" rpy="1.570795 0 0" />
      <geometry>
          <cylinder length="0.01" radius="0.034" />
      </geometry>
    </visual>
  </link>
  <joint name="joint_left_wheel" type="continuous">
    <parent link="base_link"/>
    <child link="left_wheel"/>
    <origin xyz="0 0.1 0" rpy="0 0 0" /> 
    <axis xyz="0 1 0" />
  </joint>
</robot>
